Workbook

Sheet Step One Know the Basics
B1: Guide2Go Steps to Overseas Travel WORKBOOK
B3: Instructions: Fill in the white cells following the Steps to Overseas Guide.
B4: STEP ONE: Know the Basics
B5: 1. Who is going?
B6: Names | D6: me, Aldo, Julien
B7: Number of people Do not include people under age 2 | D7: 3
B8: 2. What time of year are you going?
B9: Spring
B10: 3. How long are you going?
B11: 2 weeks
B12: 4. Where are you going?
B13: City | C13: Country | D13: Number of nights per city
B14: Paris | C14: France | D14: 3
B15: Lyon | C15: France | D15: 2
B16: Bordeaux | C16: France | D16: 2
B17: Barcelona | C17: Spain | D17: 3
B18: Madrid | C18: Spain | D18: 2
B20: Total number of nights | D20: =SUM(D14:D19) -> 12
B21: Total number of days | D21: =D20+1 -> 13

Sheet Step Two Afford and Save
B1: Guide2Go Steps to Overseas Travel WORKBOOK | I1: The earliest date I can book the flights is
I2: If using cash only for flights, the earliest date I can book flights is
B3: Instructions: Fill in the white cells following the Steps to Overseas Guide.
B4: Update cells 10 and 130 every month.
B5: STEP TWO: Afford and Save
B6: 1. Flight costs - Consider completing both strategies and choosing the best one.
B7: Strategy 1: Use credit card points or a combination of points and cash.
B8: Which credit card am I using? | E8: Chase Sapphire
B9: How many points do I need to save for everyone's flights there and back? | E9: 200000
B10: How many points do I have now? **Update this amount every month** | E10: 25000
B11: Remaining points needed. | E11: =E9-E10 -> 175000
B12: How many points will I earn each month? | E12: 15000
B13: Number of months to save all the points. | E13: =E9/E12 -> 13.333333
B14: Months left to save all the points. | E14: =E11/E12 -> 11.666667
B15: Strategy 2: Use cash only.
B16: How much will everyone's flights there and back cost? | E16: 4500
B17: How much cash do I have now for flights? | E17: 500
B18: Remaining cash needed. | E18: =E16-E17 -> 4000
B19: How much cash can I save per month for flights? | E19: 400
B20: Number of months to save total amount. | E20: =E16/E19 -> 11.25
B21: Months left to save total amount. | E21: =E18/E19 -> 10
B22: Decide: Which strategy did I choose?
B23: Points
B24: If using points, add estimate of any cash needed (taxes, fees, etc.) | E24: 700
B25: Total estimated flight cost | E25: =IF(B23="Cash only",E16,E24) -> 700
B26: 2. Housing costs
B27: Cities | C27: Total cost per city | D27: ='Step One Know the Basics'!D19
B28: ='Step One Know the Basics'!B14 -> Paris | C28: 625
B29: ='Step One Know the Basics'!B15 -> Lyon | C29: 275
B30: ='Step One Know the Basics'!B16 -> Bordeaux | C30: 425
B31: ='Step One Know the Basics'!B17 -> Barcelona | C31: 700
B32: ='Step One Know the Basics'!B18 -> Madrid | C32: 350
B33: ='Step One Know the Basics'!B19
B34: Total estimated housing cost | E34: =SUM(C28+C29+C30+C31+C32+C33) -> 2375
B35: 3. Food costs
B36: Total number of days | E36: ='Step One Know the Basics'!D21 -> 13
B37: Number of days eating budget meals | E37: 8
B38: Number of days eating moderate meals | E38: 6
B39: Estimated cost | E39: =(E37*50)+(E38*80)*'Step One Know the Basics'!D7 -> 1840
B40: Number of days in expensive countries | E40: 0
...

Sheet Step Three Book Your Trip
B1: Guide2Go Steps to Overseas Travel WORKBOOK
B3: Instructions: Fill in the white cells following the Steps to Overseas Guide.
B4: STEP THREE: Book Your Trip
B5: 1. Booking flights
B6: Airline | D6: American Airlines
B7: Outbound flight date | D7: 46089
B8: Return flight date | D8: 46102
B9: Did I reserve the seats? | D9: No
B10: Did I pay for checked bags? | D10: Yes
B11: Are all passports valid within 6 months from the end date of my trip? | D11: Yes
B12: If going to Europe, did I complete the ETIAS travel authorization? | D12: No
B13: What did I pay for the flights, including bags and seats? | D13: Total Amount Paid: Flights | F13: 700
D14: Amount I am under or over (red) budget for flights | F14: ='Step Two Afford and Save'!E25-F13 -> 0
B15: If I'm over budget: If I choose to save more, I must save this much more per month. | D15: =ABS(F14/'Step Two Afford and Save'!E132) -> 0
B16: 2. Booking housing
B17: City | C17: ='Step One Know the Basics'!B14 -> Paris
B18: Housing name | C18: Paris Court Hotel
B19: Dates | C19: 3/9/26-3/12/26
B20: Amount Paid | C20: 625
B21: City | C21: ='Step One Know the Basics'!B15 -> Lyon
B22: Housing name | C22: Best Western Lyon
B23: Dates | C23: 3/12/26-3/14/26
B24: Amount Paid | C24: 275
B25: City | C25: ='Step One Know the Basics'!B16 -> Bordeaux
B26: Housing name | C26: Airbnb Bordeaux
B27: Dates | C27: 3/14/26-3/16/26
B28: Amount Paid | C28: 450
B29: City | C29: ='Step One Know the Basics'!B17 -> Barcelona
B30: Housing name | C30: Hotel Mosaic
B31: Dates | C31: 3/16/26-3/19/26
B32: Amount Paid | C32: 725
B33: City | C33: ='Step One Know the Basics'!B18 -> Madrid
B34: Housing name | C34: Madrid Hotel
B35: Dates | C35: 3/19/26-3/21/26
B36: Amount Paid | C36: 300
B37: City | C37: ='Step One Know the Basics'!B19
B38: Housing name
B39: Dates
B40: Amount Paid
B41: Total Amount Paid: Housing | D41: =C20+C24+C28+C32+C36+C40 -> 2375
...

Sheet Final Trip Summary
B1: Guide2Go Steps to Overseas Travel WORKBOOK
B4: Trip Summary and Trip Budget
B5: Who is going?
B6: ='Step One Know the Basics'!D6 -> me, Aldo, Julien
B7: Flight Information
B8: Airline | E8: ='Step Three Book Your Trip'!D6 -> American Airlines
B9: Outbound flight date | E9: ='Step Three Book Your Trip'!D7 -> 46089
B10: Return flight date | E10: ='Step Three Book Your Trip'!D8 -> 46102
B11: Where are we going and staying?
B12: ='Step Three Book Your Trip'!C17 -> Paris | D12: ='Step Three Book Your Trip'!C21 -> Lyon | F12: ='Step Three Book Your Trip'!C25 -> Bordeaux
B13: ='Step Three Book Your Trip'!C18 -> Paris Court Hotel | D13: ='Step Three Book Your Trip'!C22 -> Best Western Lyon | F13: ='Step Three Book Your Trip'!C26 -> Airbnb Bordeaux
B14: ='Step Three Book Your Trip'!C29 -> Barcelona | D14: ='Step Three Book Your Trip'!C33 -> Madrid | F14: ='Step Three Book Your Trip'!C37
B15: ='Step Three Book Your Trip'!C30 -> Hotel Mosaic | D15: ='Step Three Book Your Trip'!C34 -> Madrid Hotel | F15: ='Step Three Book Your Trip'!C38
B16: Total amount spent: Pre-Trip | E16: ='Step Three Book Your Trip'!E130 -> 8087
B17: Total planned spending: During the Trip | E17: =SUM('Step Three Book Your Trip'!E131:G134) -> 6105
B18: Amount I can spend on food | E18: ='Step Three Book Your Trip'!E131 -> 1840
B19: Amount I can spend on non-reserved transportation | E19: ='Step Three Book Your Trip'!E132 -> 2345
B20: Amount I can spend on non-reserved fun | E20: ='Step Three Book Your Trip'!E133 -> 1170
B21: Catch-all cost | E21: ='Step Three Book Your Trip'!E134 -> 750
